Workbook

Sheet Dashboard
A1: Claude Equity Bot — Performance Dashboard
A2: Auto-updates as you fill in Price +5d/+10d/+20d on the Signals tab
A4: SIGNAL DISTRIBUTION
A5: Total Signals | B5: =COUNTA(Signals!B5:B2000)
A6: BUY Signals | B6: =COUNTIF(Signals!D5:D2000,"BUY")
A7: SELL Signals | B7: =COUNTIF(Signals!D5:D2000,"SELL")
A8: HOLD Signals | B8: =COUNTIF(Signals!D5:D2000,"HOLD")
A9: % HOLD | B9: =COUNTIF(Signals!D5:D2000,"HOLD")/COUNTA(Signals!D5:D2000)
A11: CONFIDENCE STATS
A12: Average Confidence | B12: =AVERAGE(Signals!E5:E2000)
A13: Median Confidence | B13: =MEDIAN(Signals!E5:E2000)
A14: Highest Confidence | B14: =MAX(Signals!E5:E2000)
A15: Lowest Confidence | B15: =MIN(Signals!E5:E2000)
A16: # Signals ≥ 70% (actionable) | B16: =COUNTIF(Signals!E5:E2000,">=0.7")
A17: # Signals ≥ 60% (better than coin toss) | B17: =COUNTIF(Signals!E5:E2000,">=0.6")
A18: # Signals < 45% (weak) | B18: =COUNTIF(Signals!E5:E2000,"<0.45")
A19: # Signals < 40% (very weak) | B19: =COUNTIF(Signals!E5:E2000,"<0.40")
A22: DATA QUALITY DISTRIBUTION
A23: Quality | B23: Count | C23: % of Total
A24: HIGH | B24: =COUNTIF(Signals!F5:F2000,"HIGH") | C24: =B24/SUM(B24:B26)
A25: MEDIUM | B25: =COUNTIF(Signals!F5:F2000,"MEDIUM") | C25: =B25/SUM(B24:B26)
A26: LOW | B26: =COUNTIF(Signals!F5:F2000,"LOW") | C26: =B26/SUM(B24:B26)
A29: ACCURACY BY CONFIDENCE BAND (5-Day Horizon)
A30: Updates as you fill in 5-day prices. Bands compare 'was claude right' vs total signals in each band.
A31: Confidence Band | B31: Total Signals | C31: YES (Right) | D31: NO (Wrong) | E31: Hit Rate
A32: 0-39% | B32: =COUNTIFS(Signals!E5:E2000,"<0.4",Signals!E5:E2000,"<0.4") | C32: =COUNTIFS(Signals!E5:E2000,"<0.4",Signals!E5:E2000,"<0.4",Signals!N5:N2000,"YES") | D32: =COUNTIFS(Signals!E5:E2000,"<0.4",Signals!E5:E2000,"<0.4",Signals!N5:N2000,"NO") | E32: =IFERROR(C32/(C32+D32),"-")
A33: 40-49% | B33: =COUNTIFS(Signals!E5:E2000,">=0.4",Signals!E5:E2000,"<0.5") | C33: =COUNTIFS(Signals!E5:E2000,">=0.4",Signals!E5:E2000,"<0.5",Signals!N5:N2000,"YES") | D33: =COUNTIFS(Signals!E5:E2000,">=0.4",Signals!E5:E2000,"<0.5",Signals!N5:N2000,"NO") | E33: =IFERROR(C33/(C33+D33),"-")
A34: 50-59% | B34: =COUNTIFS(Signals!E5:E2000,">=0.5",Signals!E5:E2000,"<0.6") | C34: =COUNTIFS(Signals!E5:E2000,">=0.5",Signals!E5:E2000,"<0.6",Signals!N5:N2000,"YES") | D34: =COUNTIFS(Signals!E5:E2000,">=0.5",Signals!E5:E2000,"<0.6",Signals!N5:N2000,"NO") | E34: =IFERROR(C34/(C34+D34),"-")
A35: 60-69% | B35: =COUNTIFS(Signals!E5:E2000,">=0.6",Signals!E5:E2000,"<0.7") | C35: =COUNTIFS(Signals!E5:E2000,">=0.6",Signals!E5:E2000,"<0.7",Signals!N5:N2000,"YES") | D35: =COUNTIFS(Signals!E5:E2000,">=0.6",Signals!E5:E2000,"<0.7",Signals!N5:N2000,"NO") | E35: =IFERROR(C35/(C35+D35),"-")
A36: 70-79% | B36: =COUNTIFS(Signals!E5:E2000,">=0.7",Signals!E5:E2000,"<0.8") | C36: =COUNTIFS(Signals!E5:E2000,">=0.7",Signals!E5:E2000,"<0.8",Signals!N5:N2000,"YES") | D36: =COUNTIFS(Signals!E5:E2000,">=0.7",Signals!E5:E2000,"<0.8",Signals!N5:N2000,"NO") | E36: =IFERROR(C36/(C36+D36),"-")
A37: 80-100% | B37: =COUNTIFS(Signals!E5:E2000,">=0.8",Signals!E5:E2000,"<=1") | C37: =COUNTIFS(Signals!E5:E2000,">=0.8",Signals!E5:E2000,"<=1",Signals!N5:N2000,"YES") | D37: =COUNTIFS(Signals!E5:E2000,">=0.8",Signals!E5:E2000,"<=1",Signals!N5:N2000,"NO") | E37: =IFERROR(C37/(C37+D37),"-")
A40: ACCURACY BY DATA QUALITY (5-Day Horizon)
A41: Data Quality | B41: Total | C41: YES | D41: NO | E41: Hit Rate
A42: HIGH | B42: =COUNTIF(Signals!F5:F2000,"HIGH") | C42: =COUNTIFS(Signals!F5:F2000,"HIGH",Signals!N5:N2000,"YES") | D42: =COUNTIFS(Signals!F5:F2000,"HIGH",Signals!N5:N2000,"NO") | E42: =IFERROR(C42/(C42+D42),"-")
A43: MEDIUM | B43: =COUNTIF(Signals!F5:F2000,"MEDIUM") | C43: =COUNTIFS(Signals!F5:F2000,"MEDIUM",Signals!N5:N2000,"YES") | D43: =COUNTIFS(Signals!F5:F2000,"MEDIUM",Signals!N5:N2000,"NO") | E43: =IFERROR(C43/(C43+D43),"-")
A44: LOW | B44: =COUNTIF(Signals!F5:F2000,"LOW") | C44: =COUNTIFS(Signals!F5:F2000,"LOW",Signals!N5:N2000,"YES") | D44: =COUNTIFS(Signals!F5:F2000,"LOW",Signals!N5:N2000,"NO") | E44: =IFERROR(C44/(C44+D44),"-")
A47: FILL-IN PROGRESS
A48: Tracks how much outcome data has been entered. Update Price +5d/+10d/+20d on Signals tab.
A49: Total Signals | B49: =COUNTA(Signals!B5:B2000)
A50: Filled-in 5-Day Prices | B50: =COUNT(Signals!H5:H2000)
...

Sheet Signals
A1: Claude Equity Bot — Signal Outcome Tracker
A2: Yellow cells = fill in manually as time passes | Gray cells = auto-calculated | Formulas update as you enter prices
A4: Date | B4: Ticker | C4: Account | D4: Signal | E4: Conf % | F4: Data Quality | G4: Price at Signal | H4: Price +5d | I4: Price +10d | J4: Price +20d | K4: Return +5d | L4: Return +10d | M4: Return +20d | N4: Was Claude Right? (5d) | O4: Notes / Outcome
A5: 46160 | B5: WMT | C5: Roth IRA,Individual | D5: HOLD | E5: 0.62 | F5: MEDIUM | G5: 133.31 | H5: 118.57 | I5: 113.06 | J5: 121.03 | K5: =IF(H5="","",(H5-G5)/G5) | L5: =IF(I5="","",(I5-G5)/G5) | M5: =IF(J5="","",(J5-G5)/G5) | N5: =IF(H5="","",IF(D5="HOLD",IF(ABS(K5)<0.03,"YES","NO"),IF(D5="BUY",IF(K5>0,"YES","NO"),IF(D5="SELL",IF(K5<0,"YES","NO"),""))))
A6: 46160 | B6: NTR | C6: Roth IRA | D6: HOLD | E6: 0.58 | F6: MEDIUM | G6: 71.78 | H6: 69.94 | I6: 68.5 | J6: 65.48 | K6: =IF(H6="","",(H6-G6)/G6) | L6: =IF(I6="","",(I6-G6)/G6) | M6: =IF(J6="","",(J6-G6)/G6) | N6: =IF(H6="","",IF(D6="HOLD",IF(ABS(K6)<0.03,"YES","NO"),IF(D6="BUY",IF(K6>0,"YES","NO"),IF(D6="SELL",IF(K6<0,"YES","NO"),""))))
A7: 46160 | B7: MSFT | C7: Roth IRA,Individual | D7: HOLD | E7: 0.52 | F7: MEDIUM | G7: 423.03 | H7: 416.03 | I7: 441.31 | J7: 393.83 | K7: =IF(H7="","",(H7-G7)/G7) | L7: =IF(I7="","",(I7-G7)/G7) | M7: =IF(J7="","",(J7-G7)/G7) | N7: =IF(H7="","",IF(D7="HOLD",IF(ABS(K7)<0.03,"YES","NO"),IF(D7="BUY",IF(K7>0,"YES","NO"),IF(D7="SELL",IF(K7<0,"YES","NO"),""))))
A8: 46160 | B8: NKE | C8: Roth IRA | D8: HOLD | E8: 0.45 | F8: MEDIUM | G8: 42.51 | H8: 44.94 | I8: 43.73 | J8: 45.04 | K8: =IF(H8="","",(H8-G8)/G8) | L8: =IF(I8="","",(I8-G8)/G8) | M8: =IF(J8="","",(J8-G8)/G8) | N8: =IF(H8="","",IF(D8="HOLD",IF(ABS(K8)<0.03,"YES","NO"),IF(D8="BUY",IF(K8>0,"YES","NO"),IF(D8="SELL",IF(K8<0,"YES","NO"),""))))
A9: 46160 | B9: SCHD | C9: Roth IRA | D9: HOLD | E9: 0.65 | F9: MEDIUM | G9: 32.04 | H9: 32.67 | I9: 32.37 | J9: 32.53 | K9: =IF(H9="","",(H9-G9)/G9) | L9: =IF(I9="","",(I9-G9)/G9) | M9: =IF(J9="","",(J9-G9)/G9) | N9: =IF(H9="","",IF(D9="HOLD",IF(ABS(K9)<0.03,"YES","NO"),IF(D9="BUY",IF(K9>0,"YES","NO"),IF(D9="SELL",IF(K9<0,"YES","NO"),""))))
A10: 46160 | B10: AAPL | C10: Roth IRA | D10: HOLD | E10: 0.52 | F10: MEDIUM | G10: 297.71 | H10: 308.33 | I10: 315.2 | J10: 299.24 | K10: =IF(H10="","",(H10-G10)/G10) | L10: =IF(I10="","",(I10-G10)/G10) | M10: =IF(J10="","",(J10-G10)/G10) | N10: =IF(H10="","",IF(D10="HOLD",IF(ABS(K10)<0.03,"YES","NO"),IF(D10="BUY",IF(K10>0,"YES","NO"),IF(D10="SELL",IF(K10<0,"YES","NO"),""))))
A11: 46160 | B11: DOW | C11: Roth IRA,Individual | D11: HOLD | E11: 0.52 | F11: MEDIUM | G11: 38.6 | H11: 35.28 | I11: 34.72 | J11: 32.96 | K11: =IF(H11="","",(H11-G11)/G11) | L11: =IF(I11="","",(I11-G11)/G11) | M11: =IF(J11="","",(J11-G11)/G11) | N11: =IF(H11="","",IF(D11="HOLD",IF(ABS(K11)<0.03,"YES","NO"),IF(D11="BUY",IF(K11>0,"YES","NO"),IF(D11="SELL",IF(K11<0,"YES","NO"),""))))
A12: 46160 | B12: AIQ | C12: Roth IRA,Individual | D12: HOLD | E12: 0.55 | F12: MEDIUM | G12: 60.73 | H12: 65.2 | I12: 70.14 | J12: 64.64 | K12: =IF(H12="","",(H12-G12)/G12) | L12: =IF(I12="","",(I12-G12)/G12) | M12: =IF(J12="","",(J12-G12)/G12) | N12: =IF(H12="","",IF(D12="HOLD",IF(ABS(K12)<0.03,"YES","NO"),IF(D12="BUY",IF(K12>0,"YES","NO"),IF(D12="SELL",IF(K12<0,"YES","NO"),""))))
A13: 46160 | B13: JPM | C13: Roth IRA | D13: HOLD | E13: 0.52 | F13: MEDIUM | G13: 300.97 | H13: 306.74 | I13: 300.96 | J13: 331.14 | K13: =IF(H13="","",(H13-G13)/G13) | L13: =IF(I13="","",(I13-G13)/G13) | M13: =IF(J13="","",(J13-G13)/G13) | N13: =IF(H13="","",IF(D13="HOLD",IF(ABS(K13)<0.03,"YES","NO"),IF(D13="BUY",IF(K13>0,"YES","NO"),IF(D13="SELL",IF(K13<0,"YES","NO"),""))))
A14: 46160 | B14: GM | C14: Roth IRA,Individual | D14: HOLD | E14: 0.42 | F14: MEDIUM | G14: 73.11 | H14: 79.79 | I14: 81.73 | J14: 82.51 | K14: =IF(H14="","",(H14-G14)/G14) | L14: =IF(I14="","",(I14-G14)/G14) | M14: =IF(J14="","",(J14-G14)/G14) | N14: =IF(H14="","",IF(D14="HOLD",IF(ABS(K14)<0.03,"YES","NO"),IF(D14="BUY",IF(K14>0,"YES","NO"),IF(D14="SELL",IF(K14<0,"YES","NO"),""))))
A15: 46160 | B15: PWR | C15: Roth IRA | D15: HOLD | E15: 0.55 | F15: MEDIUM | G15: 722.69 | H15: 742.18 | I15: 706.06 | J15: 719.29 | K15: =IF(H15="","",(H15-G15)/G15) | L15: =IF(I15="","",(I15-G15)/G15) | M15: =IF(J15="","",(J15-G15)/G15) | N15: =IF(H15="","",IF(D15="HOLD",IF(ABS(K15)<0.03,"YES","NO"),IF(D15="BUY",IF(K15>0,"YES","NO"),IF(D15="SELL",IF(K15<0,"YES","NO"),""))))
A16: 46160 | B16: XLU | C16: Roth IRA | D16: HOLD | E16: 0.52 | F16: MEDIUM | G16: 43.92 | H16: 45.33 | I16: 43.9 | J16: 45.06 | K16: =IF(H16="","",(H16-G16)/G16) | L16: =IF(I16="","",(I16-G16)/G16) | M16: =IF(J16="","",(J16-G16)/G16) | N16: =IF(H16="","",IF(D16="HOLD",IF(ABS(K16)<0.03,"YES","NO"),IF(D16="BUY",IF(K16>0,"YES","NO"),IF(D16="SELL",IF(K16<0,"YES","NO"),""))))
... A50: 46161 | B50: VTI | C50: Scout | D50: HOLD | E50: 0.52 | F50: MEDIUM | G50: 359.51 | H50: 369.36 | I50: 371.65 | J50: 365.76 | K50: =IF(H50="","",(H50-G50)/G50) | L50: =IF(I50="","",(I50-G50)/G50) | M50: =IF(J50="","",(J50-G50)/G50) | N50: =IF(H50="","",IF(D50="HOLD",IF(ABS(K50)<0.03,"YES","NO"),IF(D50="BUY",IF(K50>0,"YES","NO"),IF(D50="SELL",IF(K50<0,"YES","NO"),""))))
A51: 46161 | B51: NVDA | C51: Scout | D51: BUY | E51: 0.62 | F51: MEDIUM | G51: 220.58 | H51: 212.6 | I51: 214.75 | J51: 204.65 | K51: =IF(H51="","",(H51-G51)/G51) | L51: =IF(I51="","",(I51-G51)/G51) | M51: =IF(J51="","",(J51-G51)/G51) | N51: =IF(H51="","",IF(D51="HOLD",IF(ABS(K51)<0.03,"YES","NO"),IF(D51="BUY",IF(K51>0,"YES","NO"),IF(D51="SELL",IF(K51<0,"YES","NO"),"")))) | O51: First BUY signal. Rejected: 62% < 70% threshold
A52: 46161 | B52: GLD | C52: Scout | D52: HOLD | E52: 0.42 | F52: MEDIUM | G52: 412.56 | H52: 404.49 | I52: 407.87 | J52: 388.6 | K52: =IF(H52="","",(H52-G52)/G52) | L52: =IF(I52="","",(I52-G52)/G52) | M52: =IF(J52="","",(J52-G52)/G52) | N52: =IF(H52="","",IF(D52="HOLD",IF(ABS(K52)<0.03,"YES","NO"),IF(D52="BUY",IF(K52>0,"YES","NO"),IF(D52="SELL",IF(K52<0,"YES","NO"),""))))
A53: 46162 | B53: AAPL | C53: Roth IRA | D53: HOLD | E53: 0.52 | F53: MEDIUM | G53: 299.43 | H53: 312.51 | I53: 311.23 | J53: 298.01 | K53: =IF(H53="","",(H53-G53)/G53) | L53: =IF(I53="","",(I53-G53)/G53) | M53: =IF(J53="","",(J53-G53)/G53) | N53: =IF(H53="","",IF(D53="HOLD",IF(ABS(K53)<0.03,"YES","NO"),IF(D53="BUY",IF(K53>0,"YES","NO"),IF(D53="SELL",IF(K53<0,"YES","NO"),""))))
A54: 46162 | B54: AG | C54: Individual | D54: HOLD | E54: 0.45 | F54: MEDIUM | G54: 19.69 | H54: 20.58 | I54: 19.77 | J54: 18 | K54: =IF(H54="","",(H54-G54)/G54) | L54: =IF(I54="","",(I54-G54)/G54) | M54: =IF(J54="","",(J54-G54)/G54) | N54: =IF(H54="","",IF(D54="HOLD",IF(ABS(K54)<0.03,"YES","NO"),IF(D54="BUY",IF(K54>0,"YES","NO"),IF(D54="SELL",IF(K54<0,"YES","NO"),""))))
A55: 46162 | B55: AIQ | C55: Roth IRA,Individual | D55: HOLD | E55: 0.45 | F55: MEDIUM | G55: 61.25 | H55: 66.34 | I55: 68.07 | J55: 66.8 | K55: =IF(H55="","",(H55-G55)/G55) | L55: =IF(I55="","",(I55-G55)/G55) | M55: =IF(J55="","",(J55-G55)/G55) | N55: =IF(H55="","",IF(D55="HOLD",IF(ABS(K55)<0.03,"YES","NO"),IF(D55="BUY",IF(K55>0,"YES","NO"),IF(D55="SELL",IF(K55<0,"YES","NO"),""))))
A56: 46162 | B56: CBRS | C56: Individual | D56: HOLD | E56: 0.42 | F56: LOW | G56: 322.42 | H56: 242.59 | I56: 215.4 | J56: 234.71 | K56: =IF(H56="","",(H56-G56)/G56) | L56: =IF(I56="","",(I56-G56)/G56) | M56: =IF(J56="","",(J56-G56)/G56) | N56: =IF(H56="","",IF(D56="HOLD",IF(ABS(K56)<0.03,"YES","NO"),IF(D56="BUY",IF(K56>0,"YES","NO"),IF(D56="SELL",IF(K56<0,"YES","NO"),""))))
A57: 46162 | B57: CORN | C57: Individual | D57: HOLD | E57: 0.42 | F57: LOW | G57: 18.5 | H57: 18.21 | I57: 17.23 | J57: 16.95 | K57: =IF(H57="","",(H57-G57)/G57) | L57: =IF(I57="","",(I57-G57)/G57) | M57: =IF(J57="","",(J57-G57)/G57) | N57: =IF(H57="","",IF(D57="HOLD",IF(ABS(K57)<0.03,"YES","NO"),IF(D57="BUY",IF(K57>0,"YES","NO"),IF(D57="SELL",IF(K57<0,"YES","NO"),""))))
A58: 46162 | B58: DOW | C58: Roth IRA,Individual | D58: HOLD | E58: 0.42 | F58: MEDIUM | G58: 36.85 | H58: 34.77 | I58: 34.79 | J58: 31.73 | K58: =IF(H58="","",(H58-G58)/G58) | L58: =IF(I58="","",(I58-G58)/G58) | M58: =IF(J58="","",(J58-G58)/G58) | N58: =IF(H58="","",IF(D58="HOLD",IF(ABS(K58)<0.03,"YES","NO"),IF(D58="BUY",IF(K58>0,"YES","NO"),IF(D58="SELL",IF(K58<0,"YES","NO"),""))))
A59: 46162 | B59: FTI | C59: Individual | D59: HOLD | E59: 0.55 | F59: MEDIUM | G59: 73.93 | H59: 67.7 | I59: 69.01 | J59: 65.17 | K59: =IF(H59="","",(H59-G59)/G59) | L59: =IF(I59="","",(I59-G59)/G59) | M59: =IF(J59="","",(J59-G59)/G59) | N59: =IF(H59="","",IF(D59="HOLD",IF(ABS(K59)<0.03,"YES","NO"),IF(D59="BUY",IF(K59>0,"YES","NO"),IF(D59="SELL",IF(K59<0,"YES","NO"),""))))
A60: 46162 | B60: GM | C60: Roth IRA,Individual | D60: HOLD | E60: 0.45 | F60: MEDIUM | G60: 74.48 | H60: 84.35 | I60: 83.22 | J60: 79.29 | K60: =IF(H60="","",(H60-G60)/G60) | L60: =IF(I60="","",(I60-G60)/G60) | M60: =IF(J60="","",(J60-G60)/G60) | N60: =IF(H60="","",IF(D60="HOLD",IF(ABS(K60)<0.03,"YES","NO"),IF(D60="BUY",IF(K60>0,"YES","NO"),IF(D60="SELL",IF(K60<0,"YES","NO"),""))))
A61: 46162 | B61: JPM | C61: Roth IRA | D61: HOLD | E61: 0.52 | F61: MEDIUM | G61: 299.5 | H61: 296.73 | I61: 310.89 | J61: 325.22 | K61: =IF(H61="","",(H61-G61)/G61) | L61: =IF(I61="","",(I61-G61)/G61) | M61: =IF(J61="","",(J61-G61)/G61) | N61: =IF(H61="","",IF(D61="HOLD",IF(ABS(K61)<0.03,"YES","NO"),IF(D61="BUY",IF(K61>0,"YES","NO"),IF(D61="SELL",IF(K61<0,"YES","NO"),""))))
A62: 46162 | B62: MSFT | C62: Roth IRA,Individual | D62: HOLD | E62: 0.52 | F62: MEDIUM | G62: 414.49 | H62: 426.99 | I62: 428.05 | J62: 379.4 | K62: =IF(H62="","",(H62-G62)/G62) | L62: =IF(I62="","",(I62-G62)/G62) | M62: =IF(J62="","",(J62-G62)/G62) | N62: =IF(H62="","",IF(D62="HOLD",IF(ABS(K62)<0.03,"YES","NO"),IF(D62="BUY",IF(K62>0,"YES","NO"),IF(D62="SELL",IF(K62<0,"YES","NO"),""))))
A63: 46162 | B63: NKE | C63: Roth IRA | D63: HOLD | E63: 0.48 | F63: MEDIUM | G63: 43.08 | H63: 47.37 | I63: 43.62 | J63: 45.2 | K63: =IF(H63="","",(H63-G63)/G63) | L63: =IF(I63="","",(I63-G63)/G63) | M63: =IF(J63="","",(J63-G63)/G63) | N63: =IF(H63="","",IF(D63="HOLD",IF(ABS(K63)<0.03,"YES","NO"),IF(D63="BUY",IF(K63>0,"YES","NO"),IF(D63="SELL",IF(K63<0,"YES","NO"),""))))
... A124: 46164 | B124: GLD | C124: Scout | D124: HOLD | E124: 0.45 | F124: MEDIUM | G124: 413.07 | H124: 411.26 | I124: 397.27 | J124: 377.32 | K124: =IF(H124="","",(H124-G124)/G124) | L124: =IF(I124="","",(I124-G124)/G124) | M124: =IF(J124="","",(J124-G124)/G124) | N124: =IF(H124="","",IF(D124="HOLD",IF(ABS(K124)<0.03,"YES","NO"),IF(D124="BUY",IF(K124>0,"YES","NO"),IF(D124="SELL",IF(K124<0,"YES","NO"),""))))
A125: 46168 | B125: AAPL | C125: Roth IRA | D125: HOLD | E125: 0.55 | F125: MEDIUM | G125: 311.185 | H125: 315.2 | I125: 290.55 | K125: =IF(H125="","",(H125-G125)/G125) | L125: =IF(I125="","",(I125-G125)/G125) | M125: =IF(J125="","",(J125-G125)/G125) | N125: =IF(H125="","",IF(D125="HOLD",IF(ABS(K125)<0.03,"YES","NO"),IF(D125="BUY",IF(K125>0,"YES","NO"),IF(D125="SELL",IF(K125<0,"YES","NO"),""))))
A126: 46168 | B126: AG | C126: Individual | D126: HOLD | E126: 0.45 | F126: MEDIUM | G126: 19.8403 | H126: 20.99 | I126: 16.54 | K126: =IF(H126="","",(H126-G126)/G126) | L126: =IF(I126="","",(I126-G126)/G126) | M126: =IF(J126="","",(J126-G126)/G126) | N126: =IF(H126="","",IF(D126="HOLD",IF(ABS(K126)<0.03,"YES","NO"),IF(D126="BUY",IF(K126>0,"YES","NO"),IF(D126="SELL",IF(K126<0,"YES","NO"),""))))
A127: 46168 | B127: AIQ | C127: Roth IRA,Individual | D127: HOLD | E127: 0.55 | F127: MEDIUM | G127: 65.05 | H127: 70.14 | I127: 63.16 | K127: =IF(H127="","",(H127-G127)/G127) | L127: =IF(I127="","",(I127-G127)/G127) | M127: =IF(J127="","",(J127-G127)/G127) | N127: =IF(H127="","",IF(D127="HOLD",IF(ABS(K127)<0.03,"YES","NO"),IF(D127="BUY",IF(K127>0,"YES","NO"),IF(D127="SELL",IF(K127<0,"YES","NO"),""))))
A128: 46168 | B128: CBRS | C128: Individual | D128: HOLD | E128: 0.42 | F128: MEDIUM | G128: 240.27 | H128: 236.52 | I128: 226.81 | K128: =IF(H128="","",(H128-G128)/G128) | L128: =IF(I128="","",(I128-G128)/G128) | M128: =IF(J128="","",(J128-G128)/G128) | N128: =IF(H128="","",IF(D128="HOLD",IF(ABS(K128)<0.03,"YES","NO"),IF(D128="BUY",IF(K128>0,"YES","NO"),IF(D128="SELL",IF(K128<0,"YES","NO"),""))))
A129: 46168 | B129: CORN | C129: Individual | D129: HOLD | E129: 0.45 | F129: MEDIUM | G129: 18.21 | H129: 17.71 | I129: 17.04 | K129: =IF(H129="","",(H129-G129)/G129) | L129: =IF(I129="","",(I129-G129)/G129) | M129: =IF(J129="","",(J129-G129)/G129) | N129: =IF(H129="","",IF(D129="HOLD",IF(ABS(K129)<0.03,"YES","NO"),IF(D129="BUY",IF(K129>0,"YES","NO"),IF(D129="SELL",IF(K129<0,"YES","NO"),""))))
A130: 46168 | B130: DOW | C130: Roth IRA,Individual | D130: HOLD | E130: 0.42 | F130: MEDIUM | G130: 35.43 | H130: 34.72 | I130: 33.22 | K130: =IF(H130="","",(H130-G130)/G130) | L130: =IF(I130="","",(I130-G130)/G130) | M130: =IF(J130="","",(J130-G130)/G130) | N130: =IF(H130="","",IF(D130="HOLD",IF(ABS(K130)<0.03,"YES","NO"),IF(D130="BUY",IF(K130>0,"YES","NO"),IF(D130="SELL",IF(K130<0,"YES","NO"),""))))
A131: 46168 | B131: FTI | C131: Individual | D131: HOLD | E131: 0.55 | F131: MEDIUM | G131: 71.71 | H131: 69.45 | I131: 68.39 | K131: =IF(H131="","",(H131-G131)/G131) | L131: =IF(I131="","",(I131-G131)/G131) | M131: =IF(J131="","",(J131-G131)/G131) | N131: =IF(H131="","",IF(D131="HOLD",IF(ABS(K131)<0.03,"YES","NO"),IF(D131="BUY",IF(K131>0,"YES","NO"),IF(D131="SELL",IF(K131<0,"YES","NO"),""))))
A132: 46168 | B132: GM | C132: Roth IRA,Individual | D132: HOLD | E132: 0.52 | F132: HIGH | G132: 79.665 | H132: 81.73 | I132: 83.76 | K132: =IF(H132="","",(H132-G132)/G132) | L132: =IF(I132="","",(I132-G132)/G132) | M132: =IF(J132="","",(J132-G132)/G132) | N132: =IF(H132="","",IF(D132="HOLD",IF(ABS(K132)<0.03,"YES","NO"),IF(D132="BUY",IF(K132>0,"YES","NO"),IF(D132="SELL",IF(K132<0,"YES","NO"),""))))
A133: 46168 | B133: JPM | C133: Roth IRA | D133: HOLD | E133: 0.55 | F133: HIGH | G133: 308.055 | H133: 300.96 | I133: 312.7 | K133: =IF(H133="","",(H133-G133)/G133) | L133: =IF(I133="","",(I133-G133)/G133) | M133: =IF(J133="","",(J133-G133)/G133) | N133: =IF(H133="","",IF(D133="HOLD",IF(ABS(K133)<0.03,"YES","NO"),IF(D133="BUY",IF(K133>0,"YES","NO"),IF(D133="SELL",IF(K133<0,"YES","NO"),""))))
A134: 46168 | B134: MSFT | C134: Roth IRA,Individual | D134: HOLD | E134: 0.52 | F134: MEDIUM | G134: 417.41 | H134: 441.31 | I134: 403.41 | K134: =IF(H134="","",(H134-G134)/G134) | L134: =IF(I134="","",(I134-G134)/G134) | M134: =IF(J134="","",(J134-G134)/G134) | N134: =IF(H134="","",IF(D134="HOLD",IF(ABS(K134)<0.03,"YES","NO"),IF(D134="BUY",IF(K134>0,"YES","NO"),IF(D134="SELL",IF(K134<0,"YES","NO"),""))))
...

Sheet Near-Miss BUYs
A1: Near-Miss BUY Signals — Threshold Calibration Cohort (auto-generated)
A2: AUTO-GENERATED from the Signals tab — do not hand-edit. BUY signals rejected by the 70% threshold (60–69% confidence). Prices/returns are sourced from Signals; +Nd dates are trading-day offsets.
A4: Signal Date | B4: Ticker | C4: Account | D4: Conf % | E4: Data Quality | F4: Price at Signal | G4: +5d Date | H4: +10d Date | I4: Price +5d | J4: Price +10d | K4: Return +5d | L4: Return +10d | M4: Was Claude Right? (5d) | N4: Was Claude Right? (10d) | O4: Notes | P4: Segment
A5: 46161 | B5: NVDA | C5: Scout | D5: 0.62 | E5: MEDIUM | F5: 220.58 | G5: 46169 | H5: 46176 | I5: 212.6 | J5: 214.75 | K5: =IF(I5<>"",I5/F5-1,"") | L5: =IF(J5<>"",J5/F5-1,"") | M5: =IF(K5<>"",IF(K5>0,"YES","NO"),"") | N5: =IF(L5<>"",IF(L5>0,"YES","NO"),"") | O5: First BUY signal. Rejected: 62% < 70% threshold | P5: LOCKED
A6: 46163 | B6: SCHD | C6: Roth IRA | D6: 0.68 | E6: HIGH | F6: 32.109 | G6: 46171 | H6: 46178 | I6: 32.5 | J6: 32.3 | K6: =IF(I6<>"",I6/F6-1,"") | L6: =IF(J6<>"",J6/F6-1,"") | M6: =IF(K6<>"",IF(K6>0,"YES","NO"),"") | N6: =IF(L6<>"",IF(L6>0,"YES","NO"),"") | P6: LOCKED
A7: 46164 | B7: NVDA | C7: Scout | D7: 0.62 | E7: MEDIUM | F7: 216.765 | G7: 46174 | H7: 46181 | I7: 224.36 | J7: 208.64 | K7: =IF(I7<>"",I7/F7-1,"") | L7: =IF(J7<>"",J7/F7-1,"") | M7: =IF(K7<>"",IF(K7>0,"YES","NO"),"") | N7: =IF(L7<>"",IF(L7>0,"YES","NO"),"") | P7: LOCKED
A8: 46168 | B8: VTI | C8: Scout | D8: 0.68 | E8: HIGH | F8: 370.15 | G8: 46175 | H8: 46182 | I8: 374.36 | J8: 363.67 | K8: =IF(I8<>"",I8/F8-1,"") | L8: =IF(J8<>"",J8/F8-1,"") | M8: =IF(K8<>"",IF(K8>0,"YES","NO"),"") | N8: =IF(L8<>"",IF(L8>0,"YES","NO"),"") | P8: LOCKED
A9: 46169 | B9: NVDA | C9: Scout | D9: 0.63 | E9: MEDIUM | F9: 209.84 | G9: 46176 | H9: 46183 | I9: 214.75 | J9: 200.42 | K9: =IF(I9<>"",I9/F9-1,"") | L9: =IF(J9<>"",J9/F9-1,"") | M9: =IF(K9<>"",IF(K9>0,"YES","NO"),"") | N9: =IF(L9<>"",IF(L9>0,"YES","NO"),"") | P9: LOCKED
A10: 46171 | B10: NVDA | C10: Scout | D10: 0.68 | E10: MEDIUM | F10: 215.95 | G10: 46178 | H10: 46185 | I10: 205.1 | J10: 205.19 | K10: =IF(I10<>"",I10/F10-1,"") | L10: =IF(J10<>"",J10/F10-1,"") | M10: =IF(K10<>"",IF(K10>0,"YES","NO"),"") | N10: =IF(L10<>"",IF(L10>0,"YES","NO"),"") | P10: LOCKED
A11: 46174 | B11: NVDA | C11: Scout | D11: 0.68 | E11: MEDIUM | F11: 221.585 | G11: 46181 | H11: 46188 | I11: 208.64 | J11: 212.45 | K11: =IF(I11<>"",I11/F11-1,"") | L11: =IF(J11<>"",J11/F11-1,"") | M11: =IF(K11<>"",IF(K11>0,"YES","NO"),"") | N11: =IF(L11<>"",IF(L11>0,"YES","NO"),"") | P11: LOCKED
A12: 46175 | B12: NVDA | C12: Scout | D12: 0.68 | E12: MEDIUM | F12: 227.93 | G12: 46182 | H12: 46189 | I12: 208.19 | J12: 207.41 | K12: =IF(I12<>"",I12/F12-1,"") | L12: =IF(J12<>"",J12/F12-1,"") | M12: =IF(K12<>"",IF(K12>0,"YES","NO"),"") | N12: =IF(L12<>"",IF(L12>0,"YES","NO"),"") | P12: EXTENDED
A13: 46176 | B13: GLD | C13: Scout | D13: 0.62 | E13: MEDIUM | F13: 408.5 | G13: 46183 | H13: 46190 | I13: 374.58 | J13: 388.6 | K13: =IF(I13<>"",I13/F13-1,"") | L13: =IF(J13<>"",J13/F13-1,"") | M13: =IF(K13<>"",IF(K13>0,"YES","NO"),"") | N13: =IF(L13<>"",IF(L13>0,"YES","NO"),"") | P13: EXTENDED
A14: 46176 | B14: NVDA | C14: Scout | D14: 0.66 | E14: MEDIUM | F14: 215.1283 | G14: 46183 | H14: 46190 | I14: 200.42 | J14: 204.65 | K14: =IF(I14<>"",I14/F14-1,"") | L14: =IF(J14<>"",J14/F14-1,"") | M14: =IF(K14<>"",IF(K14>0,"YES","NO"),"") | N14: =IF(L14<>"",IF(L14>0,"YES","NO"),"") | P14: EXTENDED
A15: 46177 | B15: NVDA | C15: Scout | D15: 0.65 | E15: MEDIUM | F15: 213.785 | G15: 46184 | H15: 46191 | I15: 204.87 | J15: 210.15 | K15: =IF(I15<>"",I15/F15-1,"") | L15: =IF(J15<>"",J15/F15-1,"") | M15: =IF(K15<>"",IF(K15>0,"YES","NO"),"") | N15: =IF(L15<>"",IF(L15>0,"YES","NO"),"") | P15: EXTENDED
A16: 46178 | B16: NVDA | C16: Scout | D16: 0.65 | E16: MEDIUM | F16: 211.975 | G16: 46185 | H16: 46195 | I16: 205.19 | J16: 208.65 | K16: =IF(I16<>"",I16/F16-1,"") | L16: =IF(J16<>"",J16/F16-1,"") | M16: =IF(K16<>"",IF(K16>0,"YES","NO"),"") | N16: =IF(L16<>"",IF(L16>0,"YES","NO"),"") | P16: EXTENDED
A17: 46181 | B17: NVDA | C17: Scout | D17: 0.68 | E17: MEDIUM | F17: 208.405 | G17: 46188 | H17: 46196 | I17: 212.45 | J17: 200.04 | K17: =IF(I17<>"",I17/F17-1,"") | L17: =IF(J17<>"",J17/F17-1,"") | M17: =IF(K17<>"",IF(K17>0,"YES","NO"),"") | N17: =IF(L17<>"",IF(L17>0,"YES","NO"),"") | P17: EXTENDED
A18: 46182 | B18: NVDA | C18: Scout | D18: 0.68 | E18: MEDIUM | F18: 207.4001 | G18: 46189 | H18: 46197 | I18: 207.41 | K18: =IF(I18<>"",I18/F18-1,"") | L18: =IF(J18<>"",J18/F18-1,"") | M18: =IF(K18<>"",IF(K18>0,"YES","NO"),"") | N18: =IF(L18<>"",IF(L18>0,"YES","NO"),"") | P18: EXTENDED
A19: 46184 | B19: NVDA | C19: Scout | D19: 0.65 | E19: MEDIUM | F19: 199.94 | G19: 46191 | H19: 46199 | I19: 210.15 | K19: =IF(I19<>"",I19/F19-1,"") | L19: =IF(J19<>"",J19/F19-1,"") | M19: =IF(K19<>"",IF(K19>0,"YES","NO"),"") | N19: =IF(L19<>"",IF(L19>0,"YES","NO"),"") | P19: EXTENDED
A20: 46185 | B20: NVDA | C20: Scout | D20: 0.62 | E20: MEDIUM | F20: 205.597 | G20: 46195 | H20: 46202 | I20: 208.65 | K20: =IF(I20<>"",I20/F20-1,"") | L20: =IF(J20<>"",J20/F20-1,"") | M20: =IF(K20<>"",IF(K20>0,"YES","NO"),"") | N20: =IF(L20<>"",IF(L20>0,"YES","NO"),"") | P20: EXTENDED
A21: 46185 | B21: VTI | C21: Scout | D21: 0.68 | E21: HIGH | F21: 365.62 | G21: 46195 | H21: 46202 | I21: 368.81 | K21: =IF(I21<>"",I21/F21-1,"") | L21: =IF(J21<>"",J21/F21-1,"") | M21: =IF(K21<>"",IF(K21>0,"YES","NO"),"") | N21: =IF(L21<>"",IF(L21>0,"YES","NO"),"") | P21: EXTENDED
A22: 46189 | B22: NVDA | C22: Scout | D22: 0.65 | E22: MEDIUM | F22: 209.12 | G22: 46197 | H22: 46204 | K22: =IF(I22<>"",I22/F22-1,"") | L22: =IF(J22<>"",J22/F22-1,"") | M22: =IF(K22<>"",IF(K22>0,"YES","NO"),"") | N22: =IF(L22<>"",IF(L22>0,"YES","NO"),"") | P22: EXTENDED
A23: 46189 | B23: VTI | C23: Scout | D23: 0.68 | E23: HIGH | F23: 372.15 | G23: 46197 | H23: 46204 | K23: =IF(I23<>"",I23/F23-1,"") | L23: =IF(J23<>"",J23/F23-1,"") | M23: =IF(K23<>"",IF(K23>0,"YES","NO"),"") | N23: =IF(L23<>"",IF(L23>0,"YES","NO"),"") | P23: EXTENDED
A25: LOCKED — final 7-of-7 verdict cohort | B25: signals on/before 2026-06-01 · immutable
A26: Near-miss BUYs (n) | B26: =COUNTIF(P5:P23,"LOCKED")
A27: Completed +5d | B27: =COUNTIFS(P5:P23,"LOCKED",I5:I23,"<>")
A28: Hit count (+5d > 0) | B28: =COUNTIFS(P5:P23,"LOCKED",M5:M23,"YES")
A29: Hit rate +5d | B29: =IFERROR(COUNTIFS(P5:P23,"LOCKED",M5:M23,"YES")/COUNTIFS(P5:P23,"LOCKED",I5:I23,"<>"),"—")
A30: Avg +5d return | B30: =IFERROR(AVERAGEIFS(K5:K23,P5:P23,"LOCKED",I5:I23,"<>"),"—")
A31: Completed +10d | B31: =COUNTIFS(P5:P23,"LOCKED",J5:J23,"<>")
A32: Hit count (+10d > 0) | B32: =COUNTIFS(P5:P23,"LOCKED",N5:N23,"YES")
A33: Hit rate +10d | B33: =IFERROR(COUNTIFS(P5:P23,"LOCKED",N5:N23,"YES")/COUNTIFS(P5:P23,"LOCKED",J5:J23,"<>"),"—")
A34: Avg +10d return | B34: =IFERROR(AVERAGEIFS(L5:L23,P5:P23,"LOCKED",J5:J23,"<>"),"—")
A36: EXTENDED — running post-lock tracking | B36: signals after 2026-06-01 · fills over time
A37: Near-miss BUYs (n) | B37: =COUNTIF(P5:P23,"EXTENDED")
A38: Completed +5d | B38: =COUNTIFS(P5:P23,"EXTENDED",I5:I23,"<>")
A39: Hit count (+5d > 0) | B39: =COUNTIFS(P5:P23,"EXTENDED",M5:M23,"YES")
A40: Hit rate +5d | B40: =IFERROR(COUNTIFS(P5:P23,"EXTENDED",M5:M23,"YES")/COUNTIFS(P5:P23,"EXTENDED",I5:I23,"<>"),"—")
A41: Avg +5d return | B41: =IFERROR(AVERAGEIFS(K5:K23,P5:P23,"EXTENDED",I5:I23,"<>"),"—")
A42: Completed +10d | B42: =COUNTIFS(P5:P23,"EXTENDED",J5:J23,"<>")
A43: Hit count (+10d > 0) | B43: =COUNTIFS(P5:P23,"EXTENDED",N5:N23,"YES")
...

Sheet Cohort Analysis
A1: Cohort Analysis — Calibration Evidence by Confidence Band
A2: Hit rate by confidence band, per cohort. Looking for the pattern: highest hit rate in 50-59%, lowest hit rate in 40-49%, with absolute returns inverse (highest abs return in lowest-conf band).
A4: Section 1: Hit Rate by Confidence Band (+5d)
A5: Cohort Date | B5: Sample (with +5d) | C5: 40-49% Hit Rate | D5: 40-49% n | E5: 50-59% Hit Rate | F5: 50-59% n | G5: 60-69% Hit Rate | H5: 60-69% n | I5: Pattern Holds?
A6: 2026-05-18 | B6: =COUNTIFS(Signals!$A:$A,$A$6,Signals!$N:$N,"YES")+COUNTIFS(Signals!$A:$A,$A$6,Signals!$N:$N,"NO") | C6: =IFERROR(COUNTIFS(Signals!$A:$A,$A$6,Signals!$E:$E,">=0.40",Signals!$E:$E,"<0.50",Signals!$N:$N,"YES")/(COUNTIFS(Signals!$A:$A,$A$6,Signals!$E:$E,">=0.40",Signals!$E:$E,"<0.50",Signals!$N:$N,"YES")+COUNTIFS(Signals!$A:$A,$A$6,Signals!$E:$E,">=0.40",Signals!$E:$E,"<0.50",Signals!$N:$N,"NO")),"") | D6: =COUNTIFS(Signals!$A:$A,$A$6,Signals!$E:$E,">=0.40",Signals!$E:$E,"<0.50",Signals!$N:$N,"YES")+COUNTIFS(Signals!$A:$A,$A$6,Signals!$E:$E,">=0.40",Signals!$E:$E,"<0.50",Signals!$N:$N,"NO") | E6: =IFERROR(COUNTIFS(Signals!$A:$A,$A$6,Signals!$E:$E,">=0.50",Signals!$E:$E,"<0.60",Signals!$N:$N,"YES")/(COUNTIFS(Signals!$A:$A,$A$6,Signals!$E:$E,">=0.50",Signals!$E:$E,"<0.60",Signals!$N:$N,"YES")+COUNTIFS(Signals!$A:$A,$A$6,Signals!$E:$E,">=0.50",Signals!$E:$E,"<0.60",Signals!$N:$N,"NO")),"") | F6: =COUNTIFS(Signals!$A:$A,$A$6,Signals!$E:$E,">=0.50",Signals!$E:$E,"<0.60",Signals!$N:$N,"YES")+COUNTIFS(Signals!$A:$A,$A$6,Signals!$E:$E,">=0.50",Signals!$E:$E,"<0.60",Signals!$N:$N,"NO") | G6: =IFERROR(COUNTIFS(Signals!$A:$A,$A$6,Signals!$E:$E,">=0.60",Signals!$E:$E,"<0.70",Signals!$N:$N,"YES")/(COUNTIFS(Signals!$A:$A,$A$6,Signals!$E:$E,">=0.60",Signals!$E:$E,"<0.70",Signals!$N:$N,"YES")+COUNTIFS(Signals!$A:$A,$A$6,Signals!$E:$E,">=0.60",Signals!$E:$E,"<0.70",Signals!$N:$N,"NO")),"") | H6: =COUNTIFS(Signals!$A:$A,$A$6,Signals!$E:$E,">=0.60",Signals!$E:$E,"<0.70",Signals!$N:$N,"YES")+COUNTIFS(Signals!$A:$A,$A$6,Signals!$E:$E,">=0.60",Signals!$E:$E,"<0.70",Signals!$N:$N,"NO") | I6: =IF(B6=0,"insufficient data",IF(AND(E6>C6,E6>G6),"✓ YES","NO"))
A7: 2026-05-19 | B7: =COUNTIFS(Signals!$A:$A,$A$7,Signals!$N:$N,"YES")+COUNTIFS(Signals!$A:$A,$A$7,Signals!$N:$N,"NO") | C7: =IFERROR(COUNTIFS(Signals!$A:$A,$A$7,Signals!$E:$E,">=0.40",Signals!$E:$E,"<0.50",Signals!$N:$N,"YES")/(COUNTIFS(Signals!$A:$A,$A$7,Signals!$E:$E,">=0.40",Signals!$E:$E,"<0.50",Signals!$N:$N,"YES")+COUNTIFS(Signals!$A:$A,$A$7,Signals!$E:$E,">=0.40",Signals!$E:$E,"<0.50",Signals!$N:$N,"NO")),"") | D7: =COUNTIFS(Signals!$A:$A,$A$7,Signals!$E:$E,">=0.40",Signals!$E:$E,"<0.50",Signals!$N:$N,"YES")+COUNTIFS(Signals!$A:$A,$A$7,Signals!$E:$E,">=0.40",Signals!$E:$E,"<0.50",Signals!$N:$N,"NO") | E7: =IFERROR(COUNTIFS(Signals!$A:$A,$A$7,Signals!$E:$E,">=0.50",Signals!$E:$E,"<0.60",Signals!$N:$N,"YES")/(COUNTIFS(Signals!$A:$A,$A$7,Signals!$E:$E,">=0.50",Signals!$E:$E,"<0.60",Signals!$N:$N,"YES")+COUNTIFS(Signals!$A:$A,$A$7,Signals!$E:$E,">=0.50",Signals!$E:$E,"<0.60",Signals!$N:$N,"NO")),"") | F7: =COUNTIFS(Signals!$A:$A,$A$7,Signals!$E:$E,">=0.50",Signals!$E:$E,"<0.60",Signals!$N:$N,"YES")+COUNTIFS(Signals!$A:$A,$A$7,Signals!$E:$E,">=0.50",Signals!$E:$E,"<0.60",Signals!$N:$N,"NO") | G7: =IFERROR(COUNTIFS(Signals!$A:$A,$A$7,Signals!$E:$E,">=0.60",Signals!$E:$E,"<0.70",Signals!$N:$N,"YES")/(COUNTIFS(Signals!$A:$A,$A$7,Signals!$E:$E,">=0.60",Signals!$E:$E,"<0.70",Signals!$N:$N,"YES")+COUNTIFS(Signals!$A:$A,$A$7,Signals!$E:$E,">=0.60",Signals!$E:$E,"<0.70",Signals!$N:$N,"NO")),"") | H7: =COUNTIFS(Signals!$A:$A,$A$7,Signals!$E:$E,">=0.60",Signals!$E:$E,"<0.70",Signals!$N:$N,"YES")+COUNTIFS(Signals!$A:$A,$A$7,Signals!$E:$E,">=0.60",Signals!$E:$E,"<0.70",Signals!$N:$N,"NO") | I7: =IF(B7=0,"insufficient data",IF(AND(E7>C7,E7>G7),"✓ YES","NO"))
A8: 2026-05-20 | B8: =COUNTIFS(Signals!$A:$A,$A$8,Signals!$N:$N,"YES")+COUNTIFS(Signals!$A:$A,$A$8,Signals!$N:$N,"NO") | C8: =IFERROR(COUNTIFS(Signals!$A:$A,$A$8,Signals!$E:$E,">=0.40",Signals!$E:$E,"<0.50",Signals!$N:$N,"YES")/(COUNTIFS(Signals!$A:$A,$A$8,Signals!$E:$E,">=0.40",Signals!$E:$E,"<0.50",Signals!$N:$N,"YES")+COUNTIFS(Signals!$A:$A,$A$8,Signals!$E:$E,">=0.40",Signals!$E:$E,"<0.50",Signals!$N:$N,"NO")),"") | D8: =COUNTIFS(Signals!$A:$A,$A$8,Signals!$E:$E,">=0.40",Signals!$E:$E,"<0.50",Signals!$N:$N,"YES")+COUNTIFS(Signals!$A:$A,$A$8,Signals!$E:$E,">=0.40",Signals!$E:$E,"<0.50",Signals!$N:$N,"NO") | E8: =IFERROR(COUNTIFS(Signals!$A:$A,$A$8,Signals!$E:$E,">=0.50",Signals!$E:$E,"<0.60",Signals!$N:$N,"YES")/(COUNTIFS(Signals!$A:$A,$A$8,Signals!$E:$E,">=0.50",Signals!$E:$E,"<0.60",Signals!$N:$N,"YES")+COUNTIFS(Signals!$A:$A,$A$8,Signals!$E:$E,">=0.50",Signals!$E:$E,"<0.60",Signals!$N:$N,"NO")),"") | F8: =COUNTIFS(Signals!$A:$A,$A$8,Signals!$E:$E,">=0.50",Signals!$E:$E,"<0.60",Signals!$N:$N,"YES")+COUNTIFS(Signals!$A:$A,$A$8,Signals!$E:$E,">=0.50",Signals!$E:$E,"<0.60",Signals!$N:$N,"NO") | G8: =IFERROR(COUNTIFS(Signals!$A:$A,$A$8,Signals!$E:$E,">=0.60",Signals!$E:$E,"<0.70",Signals!$N:$N,"YES")/(COUNTIFS(Signals!$A:$A,$A$8,Signals!$E:$E,">=0.60",Signals!$E:$E,"<0.70",Signals!$N:$N,"YES")+COUNTIFS(Signals!$A:$A,$A$8,Signals!$E:$E,">=0.60",Signals!$E:$E,"<0.70",Signals!$N:$N,"NO")),"") | H8: =COUNTIFS(Signals!$A:$A,$A$8,Signals!$E:$E,">=0.60",Signals!$E:$E,"<0.70",Signals!$N:$N,"YES")+COUNTIFS(Signals!$A:$A,$A$8,Signals!$E:$E,">=0.60",Signals!$E:$E,"<0.70",Signals!$N:$N,"NO") | I8: =IF(B8=0,"insufficient data",IF(AND(E8>C8,E8>G8),"✓ YES","NO"))
A9: 2026-05-21 | B9: =COUNTIFS(Signals!$A:$A,$A$9,Signals!$N:$N,"YES")+COUNTIFS(Signals!$A:$A,$A$9,Signals!$N:$N,"NO") | C9: =IFERROR(COUNTIFS(Signals!$A:$A,$A$9,Signals!$E:$E,">=0.40",Signals!$E:$E,"<0.50",Signals!$N:$N,"YES")/(COUNTIFS(Signals!$A:$A,$A$9,Signals!$E:$E,">=0.40",Signals!$E:$E,"<0.50",Signals!$N:$N,"YES")+COUNTIFS(Signals!$A:$A,$A$9,Signals!$E:$E,">=0.40",Signals!$E:$E,"<0.50",Signals!$N:$N,"NO")),"") | D9: =COUNTIFS(Signals!$A:$A,$A$9,Signals!$E:$E,">=0.40",Signals!$E:$E,"<0.50",Signals!$N:$N,"YES")+COUNTIFS(Signals!$A:$A,$A$9,Signals!$E:$E,">=0.40",Signals!$E:$E,"<0.50",Signals!$N:$N,"NO") | E9: =IFERROR(COUNTIFS(Signals!$A:$A,$A$9,Signals!$E:$E,">=0.50",Signals!$E:$E,"<0.60",Signals!$N:$N,"YES")/(COUNTIFS(Signals!$A:$A,$A$9,Signals!$E:$E,">=0.50",Signals!$E:$E,"<0.60",Signals!$N:$N,"YES")+COUNTIFS(Signals!$A:$A,$A$9,Signals!$E:$E,">=0.50",Signals!$E:$E,"<0.60",Signals!$N:$N,"NO")),"") | F9: =COUNTIFS(Signals!$A:$A,$A$9,Signals!$E:$E,">=0.50",Signals!$E:$E,"<0.60",Signals!$N:$N,"YES")+COUNTIFS(Signals!$A:$A,$A$9,Signals!$E:$E,">=0.50",Signals!$E:$E,"<0.60",Signals!$N:$N,"NO") | G9: =IFERROR(COUNTIFS(Signals!$A:$A,$A$9,Signals!$E:$E,">=0.60",Signals!$E:$E,"<0.70",Signals!$N:$N,"YES")/(COUNTIFS(Signals!$A:$A,$A$9,Signals!$E:$E,">=0.60",Signals!$E:$E,"<0.70",Signals!$N:$N,"YES")+COUNTIFS(Signals!$A:$A,$A$9,Signals!$E:$E,">=0.60",Signals!$E:$E,"<0.70",Signals!$N:$N,"NO")),"") | H9: =COUNTIFS(Signals!$A:$A,$A$9,Signals!$E:$E,">=0.60",Signals!$E:$E,"<0.70",Signals!$N:$N,"YES")+COUNTIFS(Signals!$A:$A,$A$9,Signals!$E:$E,">=0.60",Signals!$E:$E,"<0.70",Signals!$N:$N,"NO") | I9: =IF(B9=0,"insufficient data",IF(AND(E9>C9,E9>G9),"✓ YES","NO"))
A10: 2026-05-22 | B10: =COUNTIFS(Signals!$A:$A,$A$10,Signals!$N:$N,"YES")+COUNTIFS(Signals!$A:$A,$A$10,Signals!$N:$N,"NO") | C10: =IFERROR(COUNTIFS(Signals!$A:$A,$A$10,Signals!$E:$E,">=0.40",Signals!$E:$E,"<0.50",Signals!$N:$N,"YES")/(COUNTIFS(Signals!$A:$A,$A$10,Signals!$E:$E,">=0.40",Signals!$E:$E,"<0.50",Signals!$N:$N,"YES")+COUNTIFS(Signals!$A:$A,$A$10,Signals!$E:$E,">=0.40",Signals!$E:$E,"<0.50",Signals!$N:$N,"NO")),"") | D10: =COUNTIFS(Signals!$A:$A,$A$10,Signals!$E:$E,">=0.40",Signals!$E:$E,"<0.50",Signals!$N:$N,"YES")+COUNTIFS(Signals!$A:$A,$A$10,Signals!$E:$E,">=0.40",Signals!$E:$E,"<0.50",Signals!$N:$N,"NO") | E10: =IFERROR(COUNTIFS(Signals!$A:$A,$A$10,Signals!$E:$E,">=0.50",Signals!$E:$E,"<0.60",Signals!$N:$N,"YES")/(COUNTIFS(Signals!$A:$A,$A$10,Signals!$E:$E,">=0.50",Signals!$E:$E,"<0.60",Signals!$N:$N,"YES")+COUNTIFS(Signals!$A:$A,$A$10,Signals!$E:$E,">=0.50",Signals!$E:$E,"<0.60",Signals!$N:$N,"NO")),"") | F10: =COUNTIFS(Signals!$A:$A,$A$10,Signals!$E:$E,">=0.50",Signals!$E:$E,"<0.60",Signals!$N:$N,"YES")+COUNTIFS(Signals!$A:$A,$A$10,Signals!$E:$E,">=0.50",Signals!$E:$E,"<0.60",Signals!$N:$N,"NO") | G10: =IFERROR(COUNTIFS(Signals!$A:$A,$A$10,Signals!$E:$E,">=0.60",Signals!$E:$E,"<0.70",Signals!$N:$N,"YES")/(COUNTIFS(Signals!$A:$A,$A$10,Signals!$E:$E,">=0.60",Signals!$E:$E,"<0.70",Signals!$N:$N,"YES")+COUNTIFS(Signals!$A:$A,$A$10,Signals!$E:$E,">=0.60",Signals!$E:$E,"<0.70",Signals!$N:$N,"NO")),"") | H10: =COUNTIFS(Signals!$A:$A,$A$10,Signals!$E:$E,">=0.60",Signals!$E:$E,"<0.70",Signals!$N:$N,"YES")+COUNTIFS(Signals!$A:$A,$A$10,Signals!$E:$E,">=0.60",Signals!$E:$E,"<0.70",Signals!$N:$N,"NO") | I10: =IF(B10=0,"insufficient data",IF(AND(E10>C10,E10>G10),"✓ YES","NO"))
A11: 2026-05-26 | B11: =COUNTIFS(Signals!$A:$A,$A$11,Signals!$N:$N,"YES")+COUNTIFS(Signals!$A:$A,$A$11,Signals!$N:$N,"NO") | C11: =IFERROR(COUNTIFS(Signals!$A:$A,$A$11,Signals!$E:$E,">=0.40",Signals!$E:$E,"<0.50",Signals!$N:$N,"YES")/(COUNTIFS(Signals!$A:$A,$A$11,Signals!$E:$E,">=0.40",Signals!$E:$E,"<0.50",Signals!$N:$N,"YES")+COUNTIFS(Signals!$A:$A,$A$11,Signals!$E:$E,">=0.40",Signals!$E:$E,"<0.50",Signals!$N:$N,"NO")),"") | D11: =COUNTIFS(Signals!$A:$A,$A$11,Signals!$E:$E,">=0.40",Signals!$E:$E,"<0.50",Signals!$N:$N,"YES")+COUNTIFS(Signals!$A:$A,$A$11,Signals!$E:$E,">=0.40",Signals!$E:$E,"<0.50",Signals!$N:$N,"NO") | E11: =IFERROR(COUNTIFS(Signals!$A:$A,$A$11,Signals!$E:$E,">=0.50",Signals!$E:$E,"<0.60",Signals!$N:$N,"YES")/(COUNTIFS(Signals!$A:$A,$A$11,Signals!$E:$E,">=0.50",Signals!$E:$E,"<0.60",Signals!$N:$N,"YES")+COUNTIFS(Signals!$A:$A,$A$11,Signals!$E:$E,">=0.50",Signals!$E:$E,"<0.60",Signals!$N:$N,"NO")),"") | F11: =COUNTIFS(Signals!$A:$A,$A$11,Signals!$E:$E,">=0.50",Signals!$E:$E,"<0.60",Signals!$N:$N,"YES")+COUNTIFS(Signals!$A:$A,$A$11,Signals!$E:$E,">=0.50",Signals!$E:$E,"<0.60",Signals!$N:$N,"NO") | G11: =IFERROR(COUNTIFS(Signals!$A:$A,$A$11,Signals!$E:$E,">=0.60",Signals!$E:$E,"<0.70",Signals!$N:$N,"YES")/(COUNTIFS(Signals!$A:$A,$A$11,Signals!$E:$E,">=0.60",Signals!$E:$E,"<0.70",Signals!$N:$N,"YES")+COUNTIFS(Signals!$A:$A,$A$11,Signals!$E:$E,">=0.60",Signals!$E:$E,"<0.70",Signals!$N:$N,"NO")),"") | H11: =COUNTIFS(Signals!$A:$A,$A$11,Signals!$E:$E,">=0.60",Signals!$E:$E,"<0.70",Signals!$N:$N,"YES")+COUNTIFS(Signals!$A:$A,$A$11,Signals!$E:$E,">=0.60",Signals!$E:$E,"<0.70",Signals!$N:$N,"NO") | I11: =IF(B11=0,"insufficient data",IF(AND(E11>C11,E11>G11),"✓ YES","NO"))
A12: 2026-05-27 | B12: =COUNTIFS(Signals!$A:$A,$A$12,Signals!$N:$N,"YES")+COUNTIFS(Signals!$A:$A,$A$12,Signals!$N:$N,"NO") | C12: =IFERROR(COUNTIFS(Signals!$A:$A,$A$12,Signals!$E:$E,">=0.40",Signals!$E:$E,"<0.50",Signals!$N:$N,"YES")/(COUNTIFS(Signals!$A:$A,$A$12,Signals!$E:$E,">=0.40",Signals!$E:$E,"<0.50",Signals!$N:$N,"YES")+COUNTIFS(Signals!$A:$A,$A$12,Signals!$E:$E,">=0.40",Signals!$E:$E,"<0.50",Signals!$N:$N,"NO")),"") | D12: =COUNTIFS(Signals!$A:$A,$A$12,Signals!$E:$E,">=0.40",Signals!$E:$E,"<0.50",Signals!$N:$N,"YES")+COUNTIFS(Signals!$A:$A,$A$12,Signals!$E:$E,">=0.40",Signals!$E:$E,"<0.50",Signals!$N:$N,"NO") | E12: =IFERROR(COUNTIFS(Signals!$A:$A,$A$12,Signals!$E:$E,">=0.50",Signals!$E:$E,"<0.60",Signals!$N:$N,"YES")/(COUNTIFS(Signals!$A:$A,$A$12,Signals!$E:$E,">=0.50",Signals!$E:$E,"<0.60",Signals!$N:$N,"YES")+COUNTIFS(Signals!$A:$A,$A$12,Signals!$E:$E,">=0.50",Signals!$E:$E,"<0.60",Signals!$N:$N,"NO")),"") | F12: =COUNTIFS(Signals!$A:$A,$A$12,Signals!$E:$E,">=0.50",Signals!$E:$E,"<0.60",Signals!$N:$N,"YES")+COUNTIFS(Signals!$A:$A,$A$12,Signals!$E:$E,">=0.50",Signals!$E:$E,"<0.60",Signals!$N:$N,"NO") | G12: =IFERROR(COUNTIFS(Signals!$A:$A,$A$12,Signals!$E:$E,">=0.60",Signals!$E:$E,"<0.70",Signals!$N:$N,"YES")/(COUNTIFS(Signals!$A:$A,$A$12,Signals!$E:$E,">=0.60",Signals!$E:$E,"<0.70",Signals!$N:$N,"YES")+COUNTIFS(Signals!$A:$A,$A$12,Signals!$E:$E,">=0.60",Signals!$E:$E,"<0.70",Signals!$N:$N,"NO")),"") | H12: =COUNTIFS(Signals!$A:$A,$A$12,Signals!$E:$E,">=0.60",Signals!$E:$E,"<0.70",Signals!$N:$N,"YES")+COUNTIFS(Signals!$A:$A,$A$12,Signals!$E:$E,">=0.60",Signals!$E:$E,"<0.70",Signals!$N:$N,"NO") | I12: =IF(B12=0,"insufficient data",IF(AND(E12>C12,E12>G12),"✓ YES","NO"))
A13: 2026-05-28 | B13: =COUNTIFS(Signals!$A:$A,$A$13,Signals!$N:$N,"YES")+COUNTIFS(Signals!$A:$A,$A$13,Signals!$N:$N,"NO") | C13: =IFERROR(COUNTIFS(Signals!$A:$A,$A$13,Signals!$E:$E,">=0.40",Signals!$E:$E,"<0.50",Signals!$N:$N,"YES")/(COUNTIFS(Signals!$A:$A,$A$13,Signals!$E:$E,">=0.40",Signals!$E:$E,"<0.50",Signals!$N:$N,"YES")+COUNTIFS(Signals!$A:$A,$A$13,Signals!$E:$E,">=0.40",Signals!$E:$E,"<0.50",Signals!$N:$N,"NO")),"") | D13: =COUNTIFS(Signals!$A:$A,$A$13,Signals!$E:$E,">=0.40",Signals!$E:$E,"<0.50",Signals!$N:$N,"YES")+COUNTIFS(Signals!$A:$A,$A$13,Signals!$E:$E,">=0.40",Signals!$E:$E,"<0.50",Signals!$N:$N,"NO") | E13: =IFERROR(COUNTIFS(Signals!$A:$A,$A$13,Signals!$E:$E,">=0.50",Signals!$E:$E,"<0.60",Signals!$N:$N,"YES")/(COUNTIFS(Signals!$A:$A,$A$13,Signals!$E:$E,">=0.50",Signals!$E:$E,"<0.60",Signals!$N:$N,"YES")+COUNTIFS(Signals!$A:$A,$A$13,Signals!$E:$E,">=0.50",Signals!$E:$E,"<0.60",Signals!$N:$N,"NO")),"") | F13: =COUNTIFS(Signals!$A:$A,$A$13,Signals!$E:$E,">=0.50",Signals!$E:$E,"<0.60",Signals!$N:$N,"YES")+COUNTIFS(Signals!$A:$A,$A$13,Signals!$E:$E,">=0.50",Signals!$E:$E,"<0.60",Signals!$N:$N,"NO") | G13: =IFERROR(COUNTIFS(Signals!$A:$A,$A$13,Signals!$E:$E,">=0.60",Signals!$E:$E,"<0.70",Signals!$N:$N,"YES")/(COUNTIFS(Signals!$A:$A,$A$13,Signals!$E:$E,">=0.60",Signals!$E:$E,"<0.70",Signals!$N:$N,"YES")+COUNTIFS(Signals!$A:$A,$A$13,Signals!$E:$E,">=0.60",Signals!$E:$E,"<0.70",Signals!$N:$N,"NO")),"") | H13: =COUNTIFS(Signals!$A:$A,$A$13,Signals!$E:$E,">=0.60",Signals!$E:$E,"<0.70",Signals!$N:$N,"YES")+COUNTIFS(Signals!$A:$A,$A$13,Signals!$E:$E,">=0.60",Signals!$E:$E,"<0.70",Signals!$N:$N,"NO") | I13: =IF(B13=0,"insufficient data",IF(AND(E13>C13,E13>G13),"✓ YES","NO"))
A14: 2026-05-29 | B14: =COUNTIFS(Signals!$A:$A,$A$14,Signals!$N:$N,"YES")+COUNTIFS(Signals!$A:$A,$A$14,Signals!$N:$N,"NO") | C14: =IFERROR(COUNTIFS(Signals!$A:$A,$A$14,Signals!$E:$E,">=0.40",Signals!$E:$E,"<0.50",Signals!$N:$N,"YES")/(COUNTIFS(Signals!$A:$A,$A$14,Signals!$E:$E,">=0.40",Signals!$E:$E,"<0.50",Signals!$N:$N,"YES")+COUNTIFS(Signals!$A:$A,$A$14,Signals!$E:$E,">=0.40",Signals!$E:$E,"<0.50",Signals!$N:$N,"NO")),"") | D14: =COUNTIFS(Signals!$A:$A,$A$14,Signals!$E:$E,">=0.40",Signals!$E:$E,"<0.50",Signals!$N:$N,"YES")+COUNTIFS(Signals!$A:$A,$A$14,Signals!$E:$E,">=0.40",Signals!$E:$E,"<0.50",Signals!$N:$N,"NO") | E14: =IFERROR(COUNTIFS(Signals!$A:$A,$A$14,Signals!$E:$E,">=0.50",Signals!$E:$E,"<0.60",Signals!$N:$N,"YES")/(COUNTIFS(Signals!$A:$A,$A$14,Signals!$E:$E,">=0.50",Signals!$E:$E,"<0.60",Signals!$N:$N,"YES")+COUNTIFS(Signals!$A:$A,$A$14,Signals!$E:$E,">=0.50",Signals!$E:$E,"<0.60",Signals!$N:$N,"NO")),"") | F14: =COUNTIFS(Signals!$A:$A,$A$14,Signals!$E:$E,">=0.50",Signals!$E:$E,"<0.60",Signals!$N:$N,"YES")+COUNTIFS(Signals!$A:$A,$A$14,Signals!$E:$E,">=0.50",Signals!$E:$E,"<0.60",Signals!$N:$N,"NO") | G14: =IFERROR(COUNTIFS(Signals!$A:$A,$A$14,Signals!$E:$E,">=0.60",Signals!$E:$E,"<0.70",Signals!$N:$N,"YES")/(COUNTIFS(Signals!$A:$A,$A$14,Signals!$E:$E,">=0.60",Signals!$E:$E,"<0.70",Signals!$N:$N,"YES")+COUNTIFS(Signals!$A:$A,$A$14,Signals!$E:$E,">=0.60",Signals!$E:$E,"<0.70",Signals!$N:$N,"NO")),"") | H14: =COUNTIFS(Signals!$A:$A,$A$14,Signals!$E:$E,">=0.60",Signals!$E:$E,"<0.70",Signals!$N:$N,"YES")+COUNTIFS(Signals!$A:$A,$A$14,Signals!$E:$E,">=0.60",Signals!$E:$E,"<0.70",Signals!$N:$N,"NO") | I14: =IF(B14=0,"insufficient data",IF(AND(E14>C14,E14>G14),"✓ YES","NO"))
A15: 2026-06-01 | B15: =COUNTIFS(Signals!$A:$A,$A$15,Signals!$N:$N,"YES")+COUNTIFS(Signals!$A:$A,$A$15,Signals!$N:$N,"NO") | C15: =IFERROR(COUNTIFS(Signals!$A:$A,$A$15,Signals!$E:$E,">=0.40",Signals!$E:$E,"<0.50",Signals!$N:$N,"YES")/(COUNTIFS(Signals!$A:$A,$A$15,Signals!$E:$E,">=0.40",Signals!$E:$E,"<0.50",Signals!$N:$N,"YES")+COUNTIFS(Signals!$A:$A,$A$15,Signals!$E:$E,">=0.40",Signals!$E:$E,"<0.50",Signals!$N:$N,"NO")),"") | D15: =COUNTIFS(Signals!$A:$A,$A$15,Signals!$E:$E,">=0.40",Signals!$E:$E,"<0.50",Signals!$N:$N,"YES")+COUNTIFS(Signals!$A:$A,$A$15,Signals!$E:$E,">=0.40",Signals!$E:$E,"<0.50",Signals!$N:$N,"NO") | E15: =IFERROR(COUNTIFS(Signals!$A:$A,$A$15,Signals!$E:$E,">=0.50",Signals!$E:$E,"<0.60",Signals!$N:$N,"YES")/(COUNTIFS(Signals!$A:$A,$A$15,Signals!$E:$E,">=0.50",Signals!$E:$E,"<0.60",Signals!$N:$N,"YES")+COUNTIFS(Signals!$A:$A,$A$15,Signals!$E:$E,">=0.50",Signals!$E:$E,"<0.60",Signals!$N:$N,"NO")),"") | F15: =COUNTIFS(Signals!$A:$A,$A$15,Signals!$E:$E,">=0.50",Signals!$E:$E,"<0.60",Signals!$N:$N,"YES")+COUNTIFS(Signals!$A:$A,$A$15,Signals!$E:$E,">=0.50",Signals!$E:$E,"<0.60",Signals!$N:$N,"NO") | G15: =IFERROR(COUNTIFS(Signals!$A:$A,$A$15,Signals!$E:$E,">=0.60",Signals!$E:$E,"<0.70",Signals!$N:$N,"YES")/(COUNTIFS(Signals!$A:$A,$A$15,Signals!$E:$E,">=0.60",Signals!$E:$E,"<0.70",Signals!$N:$N,"YES")+COUNTIFS(Signals!$A:$A,$A$15,Signals!$E:$E,">=0.60",Signals!$E:$E,"<0.70",Signals!$N:$N,"NO")),"") | H15: =COUNTIFS(Signals!$A:$A,$A$15,Signals!$E:$E,">=0.60",Signals!$E:$E,"<0.70",Signals!$N:$N,"YES")+COUNTIFS(Signals!$A:$A,$A$15,Signals!$E:$E,">=0.60",Signals!$E:$E,"<0.70",Signals!$N:$N,"NO") | I15: =IF(B15=0,"insufficient data",IF(AND(E15>C15,E15>G15),"✓ YES","NO"))
A16: 2026-06-02 | B16: =COUNTIFS(Signals!$A:$A,$A$16,Signals!$N:$N,"YES")+COUNTIFS(Signals!$A:$A,$A$16,Signals!$N:$N,"NO") | C16: =IFERROR(COUNTIFS(Signals!$A:$A,$A$16,Signals!$E:$E,">=0.40",Signals!$E:$E,"<0.50",Signals!$N:$N,"YES")/(COUNTIFS(Signals!$A:$A,$A$16,Signals!$E:$E,">=0.40",Signals!$E:$E,"<0.50",Signals!$N:$N,"YES")+COUNTIFS(Signals!$A:$A,$A$16,Signals!$E:$E,">=0.40",Signals!$E:$E,"<0.50",Signals!$N:$N,"NO")),"") | D16: =COUNTIFS(Signals!$A:$A,$A$16,Signals!$E:$E,">=0.40",Signals!$E:$E,"<0.50",Signals!$N:$N,"YES")+COUNTIFS(Signals!$A:$A,$A$16,Signals!$E:$E,">=0.40",Signals!$E:$E,"<0.50",Signals!$N:$N,"NO") | E16: =IFERROR(COUNTIFS(Signals!$A:$A,$A$16,Signals!$E:$E,">=0.50",Signals!$E:$E,"<0.60",Signals!$N:$N,"YES")/(COUNTIFS(Signals!$A:$A,$A$16,Signals!$E:$E,">=0.50",Signals!$E:$E,"<0.60",Signals!$N:$N,"YES")+COUNTIFS(Signals!$A:$A,$A$16,Signals!$E:$E,">=0.50",Signals!$E:$E,"<0.60",Signals!$N:$N,"NO")),"") | F16: =COUNTIFS(Signals!$A:$A,$A$16,Signals!$E:$E,">=0.50",Signals!$E:$E,"<0.60",Signals!$N:$N,"YES")+COUNTIFS(Signals!$A:$A,$A$16,Signals!$E:$E,">=0.50",Signals!$E:$E,"<0.60",Signals!$N:$N,"NO") | G16: =IFERROR(COUNTIFS(Signals!$A:$A,$A$16,Signals!$E:$E,">=0.60",Signals!$E:$E,"<0.70",Signals!$N:$N,"YES")/(COUNTIFS(Signals!$A:$A,$A$16,Signals!$E:$E,">=0.60",Signals!$E:$E,"<0.70",Signals!$N:$N,"YES")+COUNTIFS(Signals!$A:$A,$A$16,Signals!$E:$E,">=0.60",Signals!$E:$E,"<0.70",Signals!$N:$N,"NO")),"") | H16: =COUNTIFS(Signals!$A:$A,$A$16,Signals!$E:$E,">=0.60",Signals!$E:$E,"<0.70",Signals!$N:$N,"YES")+COUNTIFS(Signals!$A:$A,$A$16,Signals!$E:$E,">=0.60",Signals!$E:$E,"<0.70",Signals!$N:$N,"NO") | I16: =IF(B16=0,"insufficient data",IF(AND(E16>C16,E16>G16),"✓ YES","NO"))
A17: 2026-06-03 | B17: =COUNTIFS(Signals!$A:$A,$A$17,Signals!$N:$N,"YES")+COUNTIFS(Signals!$A:$A,$A$17,Signals!$N:$N,"NO") | C17: =IFERROR(COUNTIFS(Signals!$A:$A,$A$17,Signals!$E:$E,">=0.40",Signals!$E:$E,"<0.50",Signals!$N:$N,"YES")/(COUNTIFS(Signals!$A:$A,$A$17,Signals!$E:$E,">=0.40",Signals!$E:$E,"<0.50",Signals!$N:$N,"YES")+COUNTIFS(Signals!$A:$A,$A$17,Signals!$E:$E,">=0.40",Signals!$E:$E,"<0.50",Signals!$N:$N,"NO")),"") | D17: =COUNTIFS(Signals!$A:$A,$A$17,Signals!$E:$E,">=0.40",Signals!$E:$E,"<0.50",Signals!$N:$N,"YES")+COUNTIFS(Signals!$A:$A,$A$17,Signals!$E:$E,">=0.40",Signals!$E:$E,"<0.50",Signals!$N:$N,"NO") | E17: =IFERROR(COUNTIFS(Signals!$A:$A,$A$17,Signals!$E:$E,">=0.50",Signals!$E:$E,"<0.60",Signals!$N:$N,"YES")/(COUNTIFS(Signals!$A:$A,$A$17,Signals!$E:$E,">=0.50",Signals!$E:$E,"<0.60",Signals!$N:$N,"YES")+COUNTIFS(Signals!$A:$A,$A$17,Signals!$E:$E,">=0.50",Signals!$E:$E,"<0.60",Signals!$N:$N,"NO")),"") | F17: =COUNTIFS(Signals!$A:$A,$A$17,Signals!$E:$E,">=0.50",Signals!$E:$E,"<0.60",Signals!$N:$N,"YES")+COUNTIFS(Signals!$A:$A,$A$17,Signals!$E:$E,">=0.50",Signals!$E:$E,"<0.60",Signals!$N:$N,"NO") | G17: =IFERROR(COUNTIFS(Signals!$A:$A,$A$17,Signals!$E:$E,">=0.60",Signals!$E:$E,"<0.70",Signals!$N:$N,"YES")/(COUNTIFS(Signals!$A:$A,$A$17,Signals!$E:$E,">=0.60",Signals!$E:$E,"<0.70",Signals!$N:$N,"YES")+COUNTIFS(Signals!$A:$A,$A$17,Signals!$E:$E,">=0.60",Signals!$E:$E,"<0.70",Signals!$N:$N,"NO")),"") | H17: =COUNTIFS(Signals!$A:$A,$A$17,Signals!$E:$E,">=0.60",Signals!$E:$E,"<0.70",Signals!$N:$N,"YES")+COUNTIFS(Signals!$A:$A,$A$17,Signals!$E:$E,">=0.60",Signals!$E:$E,"<0.70",Signals!$N:$N,"NO") | I17: =IF(B17=0,"insufficient data",IF(AND(E17>C17,E17>G17),"✓ YES","NO"))
A18: 2026-06-04 | B18: =COUNTIFS(Signals!$A:$A,$A$18,Signals!$N:$N,"YES")+COUNTIFS(Signals!$A:$A,$A$18,Signals!$N:$N,"NO") | C18: =IFERROR(COUNTIFS(Signals!$A:$A,$A$18,Signals!$E:$E,">=0.40",Signals!$E:$E,"<0.50",Signals!$N:$N,"YES")/(COUNTIFS(Signals!$A:$A,$A$18,Signals!$E:$E,">=0.40",Signals!$E:$E,"<0.50",Signals!$N:$N,"YES")+COUNTIFS(Signals!$A:$A,$A$18,Signals!$E:$E,">=0.40",Signals!$E:$E,"<0.50",Signals!$N:$N,"NO")),"") | D18: =COUNTIFS(Signals!$A:$A,$A$18,Signals!$E:$E,">=0.40",Signals!$E:$E,"<0.50",Signals!$N:$N,"YES")+COUNTIFS(Signals!$A:$A,$A$18,Signals!$E:$E,">=0.40",Signals!$E:$E,"<0.50",Signals!$N:$N,"NO") | E18: =IFERROR(COUNTIFS(Signals!$A:$A,$A$18,Signals!$E:$E,">=0.50",Signals!$E:$E,"<0.60",Signals!$N:$N,"YES")/(COUNTIFS(Signals!$A:$A,$A$18,Signals!$E:$E,">=0.50",Signals!$E:$E,"<0.60",Signals!$N:$N,"YES")+COUNTIFS(Signals!$A:$A,$A$18,Signals!$E:$E,">=0.50",Signals!$E:$E,"<0.60",Signals!$N:$N,"NO")),"") | F18: =COUNTIFS(Signals!$A:$A,$A$18,Signals!$E:$E,">=0.50",Signals!$E:$E,"<0.60",Signals!$N:$N,"YES")+COUNTIFS(Signals!$A:$A,$A$18,Signals!$E:$E,">=0.50",Signals!$E:$E,"<0.60",Signals!$N:$N,"NO") | G18: =IFERROR(COUNTIFS(Signals!$A:$A,$A$18,Signals!$E:$E,">=0.60",Signals!$E:$E,"<0.70",Signals!$N:$N,"YES")/(COUNTIFS(Signals!$A:$A,$A$18,Signals!$E:$E,">=0.60",Signals!$E:$E,"<0.70",Signals!$N:$N,"YES")+COUNTIFS(Signals!$A:$A,$A$18,Signals!$E:$E,">=0.60",Signals!$E:$E,"<0.70",Signals!$N:$N,"NO")),"") | H18: =COUNTIFS(Signals!$A:$A,$A$18,Signals!$E:$E,">=0.60",Signals!$E:$E,"<0.70",Signals!$N:$N,"YES")+COUNTIFS(Signals!$A:$A,$A$18,Signals!$E:$E,">=0.60",Signals!$E:$E,"<0.70",Signals!$N:$N,"NO") | I18: =IF(B18=0,"insufficient data",IF(AND(E18>C18,E18>G18),"✓ YES","NO"))
A19: 2026-06-05 | B19: =COUNTIFS(Signals!$A:$A,$A$19,Signals!$N:$N,"YES")+COUNTIFS(Signals!$A:$A,$A$19,Signals!$N:$N,"NO") | C19: =IFERROR(COUNTIFS(Signals!$A:$A,$A$19,Signals!$E:$E,">=0.40",Signals!$E:$E,"<0.50",Signals!$N:$N,"YES")/(COUNTIFS(Signals!$A:$A,$A$19,Signals!$E:$E,">=0.40",Signals!$E:$E,"<0.50",Signals!$N:$N,"YES")+COUNTIFS(Signals!$A:$A,$A$19,Signals!$E:$E,">=0.40",Signals!$E:$E,"<0.50",Signals!$N:$N,"NO")),"") | D19: =COUNTIFS(Signals!$A:$A,$A$19,Signals!$E:$E,">=0.40",Signals!$E:$E,"<0.50",Signals!$N:$N,"YES")+COUNTIFS(Signals!$A:$A,$A$19,Signals!$E:$E,">=0.40",Signals!$E:$E,"<0.50",Signals!$N:$N,"NO") | E19: =IFERROR(COUNTIFS(Signals!$A:$A,$A$19,Signals!$E:$E,">=0.50",Signals!$E:$E,"<0.60",Signals!$N:$N,"YES")/(COUNTIFS(Signals!$A:$A,$A$19,Signals!$E:$E,">=0.50",Signals!$E:$E,"<0.60",Signals!$N:$N,"YES")+COUNTIFS(Signals!$A:$A,$A$19,Signals!$E:$E,">=0.50",Signals!$E:$E,"<0.60",Signals!$N:$N,"NO")),"") | F19: =COUNTIFS(Signals!$A:$A,$A$19,Signals!$E:$E,">=0.50",Signals!$E:$E,"<0.60",Signals!$N:$N,"YES")+COUNTIFS(Signals!$A:$A,$A$19,Signals!$E:$E,">=0.50",Signals!$E:$E,"<0.60",Signals!$N:$N,"NO") | G19: =IFERROR(COUNTIFS(Signals!$A:$A,$A$19,Signals!$E:$E,">=0.60",Signals!$E:$E,"<0.70",Signals!$N:$N,"YES")/(COUNTIFS(Signals!$A:$A,$A$19,Signals!$E:$E,">=0.60",Signals!$E:$E,"<0.70",Signals!$N:$N,"YES")+COUNTIFS(Signals!$A:$A,$A$19,Signals!$E:$E,">=0.60",Signals!$E:$E,"<0.70",Signals!$N:$N,"NO")),"") | H19: =COUNTIFS(Signals!$A:$A,$A$19,Signals!$E:$E,">=0.60",Signals!$E:$E,"<0.70",Signals!$N:$N,"YES")+COUNTIFS(Signals!$A:$A,$A$19,Signals!$E:$E,">=0.60",Signals!$E:$E,"<0.70",Signals!$N:$N,"NO") | I19: =IF(B19=0,"insufficient data",IF(AND(E19>C19,E19>G19),"✓ YES","NO"))
A20: 2026-06-08 | B20: =COUNTIFS(Signals!$A:$A,$A$20,Signals!$N:$N,"YES")+COUNTIFS(Signals!$A:$A,$A$20,Signals!$N:$N,"NO") | C20: =IFERROR(COUNTIFS(Signals!$A:$A,$A$20,Signals!$E:$E,">=0.40",Signals!$E:$E,"<0.50",Signals!$N:$N,"YES")/(COUNTIFS(Signals!$A:$A,$A$20,Signals!$E:$E,">=0.40",Signals!$E:$E,"<0.50",Signals!$N:$N,"YES")+COUNTIFS(Signals!$A:$A,$A$20,Signals!$E:$E,">=0.40",Signals!$E:$E,"<0.50",Signals!$N:$N,"NO")),"") | D20: =COUNTIFS(Signals!$A:$A,$A$20,Signals!$E:$E,">=0.40",Signals!$E:$E,"<0.50",Signals!$N:$N,"YES")+COUNTIFS(Signals!$A:$A,$A$20,Signals!$E:$E,">=0.40",Signals!$E:$E,"<0.50",Signals!$N:$N,"NO") | E20: =IFERROR(COUNTIFS(Signals!$A:$A,$A$20,Signals!$E:$E,">=0.50",Signals!$E:$E,"<0.60",Signals!$N:$N,"YES")/(COUNTIFS(Signals!$A:$A,$A$20,Signals!$E:$E,">=0.50",Signals!$E:$E,"<0.60",Signals!$N:$N,"YES")+COUNTIFS(Signals!$A:$A,$A$20,Signals!$E:$E,">=0.50",Signals!$E:$E,"<0.60",Signals!$N:$N,"NO")),"") | F20: =COUNTIFS(Signals!$A:$A,$A$20,Signals!$E:$E,">=0.50",Signals!$E:$E,"<0.60",Signals!$N:$N,"YES")+COUNTIFS(Signals!$A:$A,$A$20,Signals!$E:$E,">=0.50",Signals!$E:$E,"<0.60",Signals!$N:$N,"NO") | G20: =IFERROR(COUNTIFS(Signals!$A:$A,$A$20,Signals!$E:$E,">=0.60",Signals!$E:$E,"<0.70",Signals!$N:$N,"YES")/(COUNTIFS(Signals!$A:$A,$A$20,Signals!$E:$E,">=0.60",Signals!$E:$E,"<0.70",Signals!$N:$N,"YES")+COUNTIFS(Signals!$A:$A,$A$20,Signals!$E:$E,">=0.60",Signals!$E:$E,"<0.70",Signals!$N:$N,"NO")),"") | H20: =COUNTIFS(Signals!$A:$A,$A$20,Signals!$E:$E,">=0.60",Signals!$E:$E,"<0.70",Signals!$N:$N,"YES")+COUNTIFS(Signals!$A:$A,$A$20,Signals!$E:$E,">=0.60",Signals!$E:$E,"<0.70",Signals!$N:$N,"NO") | I20: =IF(B20=0,"insufficient data",IF(AND(E20>C20,E20>G20),"✓ YES","NO"))
A21: 2026-06-09 | B21: =COUNTIFS(Signals!$A:$A,$A$21,Signals!$N:$N,"YES")+COUNTIFS(Signals!$A:$A,$A$21,Signals!$N:$N,"NO") | C21: =IFERROR(COUNTIFS(Signals!$A:$A,$A$21,Signals!$E:$E,">=0.40",Signals!$E:$E,"<0.50",Signals!$N:$N,"YES")/(COUNTIFS(Signals!$A:$A,$A$21,Signals!$E:$E,">=0.40",Signals!$E:$E,"<0.50",Signals!$N:$N,"YES")+COUNTIFS(Signals!$A:$A,$A$21,Signals!$E:$E,">=0.40",Signals!$E:$E,"<0.50",Signals!$N:$N,"NO")),"") | D21: =COUNTIFS(Signals!$A:$A,$A$21,Signals!$E:$E,">=0.40",Signals!$E:$E,"<0.50",Signals!$N:$N,"YES")+COUNTIFS(Signals!$A:$A,$A$21,Signals!$E:$E,">=0.40",Signals!$E:$E,"<0.50",Signals!$N:$N,"NO") | E21: =IFERROR(COUNTIFS(Signals!$A:$A,$A$21,Signals!$E:$E,">=0.50",Signals!$E:$E,"<0.60",Signals!$N:$N,"YES")/(COUNTIFS(Signals!$A:$A,$A$21,Signals!$E:$E,">=0.50",Signals!$E:$E,"<0.60",Signals!$N:$N,"YES")+COUNTIFS(Signals!$A:$A,$A$21,Signals!$E:$E,">=0.50",Signals!$E:$E,"<0.60",Signals!$N:$N,"NO")),"") | F21: =COUNTIFS(Signals!$A:$A,$A$21,Signals!$E:$E,">=0.50",Signals!$E:$E,"<0.60",Signals!$N:$N,"YES")+COUNTIFS(Signals!$A:$A,$A$21,Signals!$E:$E,">=0.50",Signals!$E:$E,"<0.60",Signals!$N:$N,"NO") | G21: =IFERROR(COUNTIFS(Signals!$A:$A,$A$21,Signals!$E:$E,">=0.60",Signals!$E:$E,"<0.70",Signals!$N:$N,"YES")/(COUNTIFS(Signals!$A:$A,$A$21,Signals!$E:$E,">=0.60",Signals!$E:$E,"<0.70",Signals!$N:$N,"YES")+COUNTIFS(Signals!$A:$A,$A$21,Signals!$E:$E,">=0.60",Signals!$E:$E,"<0.70",Signals!$N:$N,"NO")),"") | H21: =COUNTIFS(Signals!$A:$A,$A$21,Signals!$E:$E,">=0.60",Signals!$E:$E,"<0.70",Signals!$N:$N,"YES")+COUNTIFS(Signals!$A:$A,$A$21,Signals!$E:$E,">=0.60",Signals!$E:$E,"<0.70",Signals!$N:$N,"NO") | I21: =IF(B21=0,"insufficient data",IF(AND(E21>C21,E21>G21),"✓ YES","NO"))
A22: 2026-06-10 | B22: =COUNTIFS(Signals!$A:$A,$A$22,Signals!$N:$N,"YES")+COUNTIFS(Signals!$A:$A,$A$22,Signals!$N:$N,"NO") | C22: =IFERROR(COUNTIFS(Signals!$A:$A,$A$22,Signals!$E:$E,">=0.40",Signals!$E:$E,"<0.50",Signals!$N:$N,"YES")/(COUNTIFS(Signals!$A:$A,$A$22,Signals!$E:$E,">=0.40",Signals!$E:$E,"<0.50",Signals!$N:$N,"YES")+COUNTIFS(Signals!$A:$A,$A$22,Signals!$E:$E,">=0.40",Signals!$E:$E,"<0.50",Signals!$N:$N,"NO")),"") | D22: =COUNTIFS(Signals!$A:$A,$A$22,Signals!$E:$E,">=0.40",Signals!$E:$E,"<0.50",Signals!$N:$N,"YES")+COUNTIFS(Signals!$A:$A,$A$22,Signals!$E:$E,">=0.40",Signals!$E:$E,"<0.50",Signals!$N:$N,"NO") | E22: =IFERROR(COUNTIFS(Signals!$A:$A,$A$22,Signals!$E:$E,">=0.50",Signals!$E:$E,"<0.60",Signals!$N:$N,"YES")/(COUNTIFS(Signals!$A:$A,$A$22,Signals!$E:$E,">=0.50",Signals!$E:$E,"<0.60",Signals!$N:$N,"YES")+COUNTIFS(Signals!$A:$A,$A$22,Signals!$E:$E,">=0.50",Signals!$E:$E,"<0.60",Signals!$N:$N,"NO")),"") | F22: =COUNTIFS(Signals!$A:$A,$A$22,Signals!$E:$E,">=0.50",Signals!$E:$E,"<0.60",Signals!$N:$N,"YES")+COUNTIFS(Signals!$A:$A,$A$22,Signals!$E:$E,">=0.50",Signals!$E:$E,"<0.60",Signals!$N:$N,"NO") | G22: =IFERROR(COUNTIFS(Signals!$A:$A,$A$22,Signals!$E:$E,">=0.60",Signals!$E:$E,"<0.70",Signals!$N:$N,"YES")/(COUNTIFS(Signals!$A:$A,$A$22,Signals!$E:$E,">=0.60",Signals!$E:$E,"<0.70",Signals!$N:$N,"YES")+COUNTIFS(Signals!$A:$A,$A$22,Signals!$E:$E,">=0.60",Signals!$E:$E,"<0.70",Signals!$N:$N,"NO")),"") | H22: =COUNTIFS(Signals!$A:$A,$A$22,Signals!$E:$E,">=0.60",Signals!$E:$E,"<0.70",Signals!$N:$N,"YES")+COUNTIFS(Signals!$A:$A,$A$22,Signals!$E:$E,">=0.60",Signals!$E:$E,"<0.70",Signals!$N:$N,"NO") | I22: =IF(B22=0,"insufficient data",IF(AND(E22>C22,E22>G22),"✓ YES","NO"))
A23: 2026-06-11 | B23: =COUNTIFS(Signals!$A:$A,$A$23,Signals!$N:$N,"YES")+COUNTIFS(Signals!$A:$A,$A$23,Signals!$N:$N,"NO") | C23: =IFERROR(COUNTIFS(Signals!$A:$A,$A$23,Signals!$E:$E,">=0.40",Signals!$E:$E,"<0.50",Signals!$N:$N,"YES")/(COUNTIFS(Signals!$A:$A,$A$23,Signals!$E:$E,">=0.40",Signals!$E:$E,"<0.50",Signals!$N:$N,"YES")+COUNTIFS(Signals!$A:$A,$A$23,Signals!$E:$E,">=0.40",Signals!$E:$E,"<0.50",Signals!$N:$N,"NO")),"") | D23: =COUNTIFS(Signals!$A:$A,$A$23,Signals!$E:$E,">=0.40",Signals!$E:$E,"<0.50",Signals!$N:$N,"YES")+COUNTIFS(Signals!$A:$A,$A$23,Signals!$E:$E,">=0.40",Signals!$E:$E,"<0.50",Signals!$N:$N,"NO") | E23: =IFERROR(COUNTIFS(Signals!$A:$A,$A$23,Signals!$E:$E,">=0.50",Signals!$E:$E,"<0.60",Signals!$N:$N,"YES")/(COUNTIFS(Signals!$A:$A,$A$23,Signals!$E:$E,">=0.50",Signals!$E:$E,"<0.60",Signals!$N:$N,"YES")+COUNTIFS(Signals!$A:$A,$A$23,Signals!$E:$E,">=0.50",Signals!$E:$E,"<0.60",Signals!$N:$N,"NO")),"") | F23: =COUNTIFS(Signals!$A:$A,$A$23,Signals!$E:$E,">=0.50",Signals!$E:$E,"<0.60",Signals!$N:$N,"YES")+COUNTIFS(Signals!$A:$A,$A$23,Signals!$E:$E,">=0.50",Signals!$E:$E,"<0.60",Signals!$N:$N,"NO") | G23: =IFERROR(COUNTIFS(Signals!$A:$A,$A$23,Signals!$E:$E,">=0.60",Signals!$E:$E,"<0.70",Signals!$N:$N,"YES")/(COUNTIFS(Signals!$A:$A,$A$23,Signals!$E:$E,">=0.60",Signals!$E:$E,"<0.70",Signals!$N:$N,"YES")+COUNTIFS(Signals!$A:$A,$A$23,Signals!$E:$E,">=0.60",Signals!$E:$E,"<0.70",Signals!$N:$N,"NO")),"") | H23: =COUNTIFS(Signals!$A:$A,$A$23,Signals!$E:$E,">=0.60",Signals!$E:$E,"<0.70",Signals!$N:$N,"YES")+COUNTIFS(Signals!$A:$A,$A$23,Signals!$E:$E,">=0.60",Signals!$E:$E,"<0.70",Signals!$N:$N,"NO") | I23: =IF(B23=0,"insufficient data",IF(AND(E23>C23,E23>G23),"✓ YES","NO"))
A24: 2026-06-12 | B24: =COUNTIFS(Signals!$A:$A,$A$24,Signals!$N:$N,"YES")+COUNTIFS(Signals!$A:$A,$A$24,Signals!$N:$N,"NO") | C24: =IFERROR(COUNTIFS(Signals!$A:$A,$A$24,Signals!$E:$E,">=0.40",Signals!$E:$E,"<0.50",Signals!$N:$N,"YES")/(COUNTIFS(Signals!$A:$A,$A$24,Signals!$E:$E,">=0.40",Signals!$E:$E,"<0.50",Signals!$N:$N,"YES")+COUNTIFS(Signals!$A:$A,$A$24,Signals!$E:$E,">=0.40",Signals!$E:$E,"<0.50",Signals!$N:$N,"NO")),"") | D24: =COUNTIFS(Signals!$A:$A,$A$24,Signals!$E:$E,">=0.40",Signals!$E:$E,"<0.50",Signals!$N:$N,"YES")+COUNTIFS(Signals!$A:$A,$A$24,Signals!$E:$E,">=0.40",Signals!$E:$E,"<0.50",Signals!$N:$N,"NO") | E24: =IFERROR(COUNTIFS(Signals!$A:$A,$A$24,Signals!$E:$E,">=0.50",Signals!$E:$E,"<0.60",Signals!$N:$N,"YES")/(COUNTIFS(Signals!$A:$A,$A$24,Signals!$E:$E,">=0.50",Signals!$E:$E,"<0.60",Signals!$N:$N,"YES")+COUNTIFS(Signals!$A:$A,$A$24,Signals!$E:$E,">=0.50",Signals!$E:$E,"<0.60",Signals!$N:$N,"NO")),"") | F24: =COUNTIFS(Signals!$A:$A,$A$24,Signals!$E:$E,">=0.50",Signals!$E:$E,"<0.60",Signals!$N:$N,"YES")+COUNTIFS(Signals!$A:$A,$A$24,Signals!$E:$E,">=0.50",Signals!$E:$E,"<0.60",Signals!$N:$N,"NO") | G24: =IFERROR(COUNTIFS(Signals!$A:$A,$A$24,Signals!$E:$E,">=0.60",Signals!$E:$E,"<0.70",Signals!$N:$N,"YES")/(COUNTIFS(Signals!$A:$A,$A$24,Signals!$E:$E,">=0.60",Signals!$E:$E,"<0.70",Signals!$N:$N,"YES")+COUNTIFS(Signals!$A:$A,$A$24,Signals!$E:$E,">=0.60",Signals!$E:$E,"<0.70",Signals!$N:$N,"NO")),"") | H24: =COUNTIFS(Signals!$A:$A,$A$24,Signals!$E:$E,">=0.60",Signals!$E:$E,"<0.70",Signals!$N:$N,"YES")+COUNTIFS(Signals!$A:$A,$A$24,Signals!$E:$E,">=0.60",Signals!$E:$E,"<0.70",Signals!$N:$N,"NO") | I24: =IF(B24=0,"insufficient data",IF(AND(E24>C24,E24>G24),"✓ YES","NO"))
A26: ACROSS ALL COHORTS | B26: =SUM(B6:B24) | C26: =AVERAGE(C6:C24) | E26: =AVERAGE(E6:E24) | G26: =AVERAGE(G6:G24) | I26: =COUNTIF(I6:I24,"✓ YES") & " of " & (COUNTIF(I6:I24,"✓ YES")+COUNTIF(I6:I24,"NO")) & " hold (cohorts w/ +5d data)"
A29: Section 2: Hit Rate by Data Quality (+5d, all cohorts combined)
A30: Data Quality | B30: Sample (with +5d) | C30: Hit Count | D30: Hit Rate | E30: Notes
A31: HIGH | B31: =COUNTIFS(Signals!$F:$F,"HIGH",Signals!$N:$N,"YES")+COUNTIFS(Signals!$F:$F,"HIGH",Signals!$N:$N,"NO") | C31: =COUNTIFS(Signals!$F:$F,"HIGH",Signals!$N:$N,"YES") | D31: =IFERROR(C31/B31,"")
